To connect to the notebook type the following command into your local terminal:
ssh -N -J tpelletreaudur@int6-pub.snellius.surf.nl tpelletreaudur@gcn15.local.snellius.surf.nl -L 5012:localhost:5012

After connection is established in your local browser go to the address:
http://localhost:5012
[I 17:00:16.139 NotebookApp] Serving notebooks from local directory: /gpfs/home3/tpelletreaudur/Probing-GNN-representations
[I 17:00:16.145 NotebookApp] Jupyter Notebook 6.4.0 is running at:
[I 17:00:16.145 NotebookApp] http://localhost:5012/?token=85480d996c88fa230a9a11ba5632b33e62c5c77fdd9763e8
[I 17:00:16.145 NotebookApp]  or http://127.0.0.1:5012/?token=85480d996c88fa230a9a11ba5632b33e62c5c77fdd9763e8
[I 17:00:16.145 NotebookApp] Use Control-C to stop this server and shut down all kernels (twice to skip confirmation).
[C 17:00:16.155 NotebookApp] 
    
    To access the notebook, open this file in a browser:
        file:///gpfs/home3/tpelletreaudur/.local/share/jupyter/runtime/nbserver-2909716-open.html
    Or copy and paste one of these URLs:
        http://localhost:5012/?token=85480d996c88fa230a9a11ba5632b33e62c5c77fdd9763e8
     or http://127.0.0.1:5012/?token=85480d996c88fa230a9a11ba5632b33e62c5c77fdd9763e8
[I 17:00:43.114 NotebookApp] 302 GET /?token=85480d996c88fa230a9a11ba5632b33e62c5c77fdd9763e8 (::1) 0.440000ms
/sw/arch/RHEL8/EB_production/2022/software/Python/3.10.4-GCCcore-11.3.0/lib/python3.10/json/encoder.py:257: UserWarning: date_default is deprecated since jupyter_client 7.0.0. Use jupyter_client.jsonutil.json_default.
  return _iterencode(o, 0)
[W 17:00:50.079 NotebookApp] Notebook FC_probing_GIN.ipynb is not trusted
Exception in callback Task.task_wakeup(<Future finis...0043\r\n\r\n'>)
handle: <Handle Task.task_wakeup(<Future finis...0043\r\n\r\n'>)>
Traceback (most recent call last):
  File "/sw/arch/RHEL8/EB_production/2022/software/Python/3.10.4-GCCcore-11.3.0/lib/python3.10/asyncio/events.py", line 80, in _run
    self._context.run(self._callback, *self._args)
RuntimeError: Cannot enter into task <Task pending name='Task-25' coro=<HTTP1ServerConnection._server_request_loop() running at /sw/arch/RHEL8/EB_production/2022/software/IPython/8.5.0-GCCcore-11.3.0/lib/python3.10/site-packages/tornado/http1connection.py:825> wait_for=<Future finished result=b'GET /api/co...70043\r\n\r\n'> cb=[IOLoop.add_future.<locals>.<lambda>() at /sw/arch/RHEL8/EB_production/2022/software/IPython/8.5.0-GCCcore-11.3.0/lib/python3.10/site-packages/tornado/ioloop.py:687]> while another task <Task pending name='Task-2' coro=<KernelManager._async_start_kernel() running at /sw/arch/RHEL8/EB_production/2022/software/IPython/8.5.0-GCCcore-11.3.0/lib/python3.10/site-packages/jupyter_client/manager.py:75>> is being executed.
Exception in callback Task.task_wakeup(<Future finis...0043\r\n\r\n'>)
handle: <Handle Task.task_wakeup(<Future finis...0043\r\n\r\n'>)>
Traceback (most recent call last):
  File "/sw/arch/RHEL8/EB_production/2022/software/Python/3.10.4-GCCcore-11.3.0/lib/python3.10/asyncio/events.py", line 80, in _run
    self._context.run(self._callback, *self._args)
RuntimeError: Cannot enter into task <Task pending name='Task-24' coro=<HTTP1ServerConnection._server_request_loop() running at /sw/arch/RHEL8/EB_production/2022/software/IPython/8.5.0-GCCcore-11.3.0/lib/python3.10/site-packages/tornado/http1connection.py:825> wait_for=<Future finished result=b'GET /kernel...70043\r\n\r\n'> cb=[IOLoop.add_future.<locals>.<lambda>() at /sw/arch/RHEL8/EB_production/2022/software/IPython/8.5.0-GCCcore-11.3.0/lib/python3.10/site-packages/tornado/ioloop.py:687]> while another task <Task pending name='Task-2' coro=<KernelManager._async_start_kernel() running at /sw/arch/RHEL8/EB_production/2022/software/IPython/8.5.0-GCCcore-11.3.0/lib/python3.10/site-packages/jupyter_client/manager.py:75>> is being executed.
[I 17:00:50.932 NotebookApp] Kernel started: 5de8d019-3af4-4a81-adc1-5f12a0ce0f69, name: python3
[IPKernelApp] ERROR | No such comm target registered: jupyter.widget.control
[IPKernelApp] WARNING | No such comm: 4b035dae-356f-4d32-8f99-3e96bd489555
[I 17:01:59.251 NotebookApp] Starting buffering for 5de8d019-3af4-4a81-adc1-5f12a0ce0f69:5b3a9baf00d04b5498819a0018ed7ddc
Exception in callback Task.task_wakeup(<Future finis...0043\r\n\r\n'>)
handle: <Handle Task.task_wakeup(<Future finis...0043\r\n\r\n'>)>
Traceback (most recent call last):
  File "/sw/arch/RHEL8/EB_production/2022/software/Python/3.10.4-GCCcore-11.3.0/lib/python3.10/asyncio/events.py", line 80, in _run
    self._context.run(self._callback, *self._args)
RuntimeError: Cannot enter into task <Task pending name='Task-26' coro=<HTTP1ServerConnection._server_request_loop() running at /sw/arch/RHEL8/EB_production/2022/software/IPython/8.5.0-GCCcore-11.3.0/lib/python3.10/site-packages/tornado/http1connection.py:825> wait_for=<Future finished result=b'GET /api/co...70043\r\n\r\n'> cb=[IOLoop.add_future.<locals>.<lambda>() at /sw/arch/RHEL8/EB_production/2022/software/IPython/8.5.0-GCCcore-11.3.0/lib/python3.10/site-packages/tornado/ioloop.py:687]> while another task <Task pending name='Task-204' coro=<KernelManager._async_start_kernel() running at /sw/arch/RHEL8/EB_production/2022/software/IPython/8.5.0-GCCcore-11.3.0/lib/python3.10/site-packages/jupyter_client/manager.py:75>> is being executed.
Exception in callback Task.task_wakeup(<Future finis...0043\r\n\r\n'>)
handle: <Handle Task.task_wakeup(<Future finis...0043\r\n\r\n'>)>
Traceback (most recent call last):
  File "/sw/arch/RHEL8/EB_production/2022/software/Python/3.10.4-GCCcore-11.3.0/lib/python3.10/asyncio/events.py", line 80, in _run
    self._context.run(self._callback, *self._args)
RuntimeError: Cannot enter into task <Task pending name='Task-27' coro=<HTTP1ServerConnection._server_request_loop() running at /sw/arch/RHEL8/EB_production/2022/software/IPython/8.5.0-GCCcore-11.3.0/lib/python3.10/site-packages/tornado/http1connection.py:825> wait_for=<Future finished result=b'GET /kernel...70043\r\n\r\n'> cb=[IOLoop.add_future.<locals>.<lambda>() at /sw/arch/RHEL8/EB_production/2022/software/IPython/8.5.0-GCCcore-11.3.0/lib/python3.10/site-packages/tornado/ioloop.py:687]> while another task <Task pending name='Task-203' coro=<MultiKernelManager._async_start_kernel() running at /sw/arch/RHEL8/EB_production/2022/software/IPython/8.5.0-GCCcore-11.3.0/lib/python3.10/site-packages/jupyter_client/multikernelmanager.py:212>> is being executed.
[I 17:02:04.190 NotebookApp] Kernel started: 88a01d50-4ad9-48d7-b8a3-b33c45cd9be4, name: python3
[IPKernelApp] ERROR | No such comm target registered: jupyter.widget.control
[IPKernelApp] WARNING | No such comm: 3a4025e1-a85e-4637-bb11-75873f7ee7cc
[I 17:03:02.032 NotebookApp] Starting buffering for 88a01d50-4ad9-48d7-b8a3-b33c45cd9be4:48d8121fb16e45318ee3067ac9e6ff7b
slurmstepd: error: *** JOB 7341003 ON gcn15 CANCELLED AT 2024-08-05T17:03:16 ***

JOB STATISTICS
==============
Job ID: 7341003
Cluster: snellius
User/Group: tpelletreaudur/tpelletreaudur
State: CANCELLED (exit code 0)
Nodes: 1
Cores per node: 18
CPU Utilized: 00:00:03
CPU Efficiency: 0.09% of 00:58:12 core-walltime
Job Wall-clock time: 00:03:14
Memory Utilized: 3.27 GB
Memory Efficiency: 2.72% of 120.00 GB
